Workbook

Sheet Model
F2: LTM | G2: % of | M2: LTM | N2: % of | S2: Transaction Value Build
B3: Sources | E3: $m | F3: EBITDA(x) | G3: Total | I3: Uses | L3: $m | M3: EBITDA(x) | N3: Total | S3: Share Price | V3: 108.3 | X3: Basic Shares Outstanding | AA3: ='Financial Performance'!Q20
B4: Revolver | E4: 0 | F4: =E4/U$11 | G4: =E4/E$8 | I4: Purchase TEV | L4: =V10 | M4: =L4/U$11 | N4: =L4/L$8 | S4: (x) Premium | V4: 0.2 | X4: (+) RSUs | AA4: 0.146
B5: Term Loan | E5: =F5*U$11 | F5: 5.5 | G5: =E5/E$8 | I5: Cash to Balance Sheet | L5: 20 | M5: =L5/U$11 | N5: =L5/L$8 | S5: Offer Price | V5: =(1+V4)*V3 | X5: (+) PSUs | Y5: Total | Z5: Strike $ | AA5: 0.169
B6: Senior Notes | E6: =F6*U$11 | F6: 2 | G6: =E6/E$8 | I6: Financing Fee | K6: 0.02 | L6: =K6*SUM(E5:E6) | M6: =L6/U$11 | N6: =L6/L$8 | S6: (x) FDSO | V6: =AA7 | X6: ITM Options | Y6: 0 | Z6: NA | AA6: =IF(Z6="NA",0,IF(Z6<=V5,Y6-((Y6*Z6)/V5),0))
B7: Sponsor Equity | E7: =E8-SUM(E4:E6) | F7: =E7/U$11 | G7: =E7/E$8 | I7: M&A Fees | K7: 0.0075 | L7: =K7*L4 | M7: =L7/U$11 | N7: =L7/L$8 | S7: Equity Purchase Price | V7: =V6*V5 | X7: FDSO | AA7: =SUM(AA3:AA6)
B8: Total Sources | E8: =L8 | F8: =E8/U$11 | G8: =SUM(G4:G7) | I8: Total Uses | L8: =SUM(L4:L7) | M8: =L8/U$11 | N8: =SUM(N4:N7) | S8: (+) Debt | V8: ='Financial Performance'!S20
S9: (-) Cash | V9: =-'Financial Performance'!T20
B10: Income Statement | S10: Implied Enterprise Value | V10: =SUM(V7:V9)
B11: Period | E11: Historical | I11: Guidance | J11: Hold Period | O11: Extrap. | P11: CAGR | S11: LTM EBITDA(x) | U11: =SUM('Financial Performance'!J17:J20) | V11: =V$10/$U11
B12: Fiscal Year | C12: 2019 | D12: =C12+1 | E12: =D12+1 | F12: =E12+1 | G12: =F12+1 | H12: =G12+1 | I12: =H12+1 | J12: =I12+1 | K12: =J12+1 | ... O12: =N12+1 | P12: '19A-'24A | Q12: '25E-'30A | S12: 2025E EBITDA(x) | U12: =I35 | V12: =V$10/$U12
B13: State & Local Government | E13: =E15*E$22 | F13: =F15*F$22 | G13: =G15*G$22 | H13: =H15*H$22 | I13: =I15*I$22 | J13: =(1+J14)*I13 | K13: =(1+K14)*J13 | L13: =(1+L14)*K13 | M13: =(1+M14)*L13 | N13: =(1+N14)*M13 | O13: =(1+O14)*N13 | Q13: =(N13/I13)^(1/5)-1 | S13: NTM EBITDA(x) | U13: =(I35*0.25)+(J35*0.75) | V13: =V$10/$U13
B14: Growth % | F14: =(F13/E13)-1 | G14: =(G13/F13)-1 | H14: =(H13/G13)-1 | I14: =(I13/H13)-1 | J14: =I14+($N14-$I14)/5 | K14: =J14+($N14-$I14)/5 | L14: =K14+($N14-$I14)/5 | M14: =L14+($N14-$I14)/5 | N14: 0.08 | O14: =N14
B15: Contract Revenue % | E15: 0.36 | F15: 0.45 | G15: 0.47 | H15: 0.47 | I15: 0.44 | J15: =J13/J$22 | K15: =K13/K$22 | L15: =L13/L$22 | M15: =M13/M$22 | N15: =N13/N$22 | O15: =O13/O$22 | S15: Returns at Exit | W15: 1 | X15: =W15+1 | Y15: =X15+1 | Z15: =Y15+1 | AA15: =Z15+1
B16: Utilities | E16: =E18*E$22 | F16: =F18*F$22 | G16: =G18*G$22 | H16: =H18*H$22 | I16: =I18*I$22 | J16: =(1+J17)*I16 | K16: =(1+K17)*J16 | L16: =(1+L17)*K16 | M16: =(1+M17)*L16 | N16: =(1+N17)*M16 | O16: =(1+O17)*N16 | Q16: =(N16/I16)^(1/5)-1 | S16: Exit NTM EBITDA | W16: =K35 | X16: =L35 | Y16: =M35 | Z16: =N35 | AA16: =O35
B17: Growth % | F17: =(F16/E16)-1 | G17: =(G16/F16)-1 | H17: =(H16/G16)-1 | I17: =(I16/H16)-1 | J17: =I17+($N17-$I17)/5 | K17: =J17+($N17-$I17)/5 | L17: =K17+($N17-$I17)/5 | M17: =L17+($N17-$I17)/5 | N17: 0.08 | O17: =N17 | S17: (x) Exit NTM Multiple | W17: 21 | X17: =W17 | Y17: =X17 | Z17: =Y17 | AA17: =Z17
B18: Contract Revenue % | E18: 0.56 | F18: 0.47 | G18: 0.46 | H18: 0.46 | I18: 0.41 | J18: =J16/J$22 | K18: =K16/K$22 | L18: =L16/L$22 | M18: =M16/M$22 | N18: =N16/N$22 | O18: =O16/O$22 | S18: Total Exit Enterprise Value | W18: =W17*W16 | X18: =X17*X16 | Y18: =Y17*Y16 | Z18: =Z17*Z16 | AA18: =AA17*AA16
B19: Commercial | E19: =E21*E$22 | F19: =F21*F$22 | G19: =G21*G$22 | H19: =H21*H$22 | I19: =I21*I$22 | J19: =(1+J20)*I19 | K19: =(1+K20)*J19 | L19: =(1+L20)*K19 | M19: =(1+M20)*L19 | N19: =(1+N20)*M19 | O19: =(1+O20)*N19 | Q19: =(N19/I19)^(1/5)-1 | S19: (-) Net Debt | W19: =-J123 | X19: =-K123 | Y19: =-L123 | Z19: =-M123 | AA19: =-N123
B20: Growth % | F20: =(F19/E19)-1 | G20: =(G19/F19)-1 | H20: =(H19/G19)-1 | I20: =(I19/H19)-1 | J20: 0.75 | K20: 0.3 | L20: 0.15 | M20: 0.1 | N20: 0.1 | O20: =N20 | S20: Total Exit Equity Value | W20: =W18+W19 | X20: =X18+X19 | Y20: =Y18+Y19 | Z20: =Z18+Z19 | AA20: =AA18+AA19
B21: Contract Revenue % | E21: 0.08 | F21: 0.08 | G21: 0.07 | H21: 0.07 | I21: 0.15 | J21: =J19/J$22 | K21: =K19/K$22 | L21: =L19/L$22 | M21: =M19/M$22 | N21: =N19/N$22 | O21: =O19/O$22 | S21: (+) Management Options Proceeds | V21: 0.08 | W21: =IF(W20>$E7,$E7*$V21,0) | X21: =IF(X20>$E7,$E7*$V21,0) | Y21: =IF(Y20>$E7,$E7*$V21,0) | Z21: =IF(Z20>$E7,$E7*$V21,0) | AA21: =IF(AA20>$E7,$E7*$V21,0)
B22: Total Contract Revenue | C22: =INDEX('Financial Overview'!C8:I8,MATCH(C12,'Financial Overview'!C3:I3,0)) | D22: ='Financial Overview'!E8 | E22: ='Financial Overview'!F8 | F22: ='Financial Overview'!G8 | G22: ='Financial Overview'!H8 | H22: ='Financial Overview'!I8 | I22: =I26/(1-I25) | J22: =SUM(J13,J16,J19) | K22: =SUM(K13,K16,K19) | L22: =SUM(L13,L16,L19) | M22: =SUM(M13,M16,M19) | N22: =SUM(N13,N16,N19) | O22: =SUM(O13,O16,O19) | P22: =(H22/C22)^(1/5)-1 | Q22: =(N22/I22)^(1/5)-1 | S22: (-) Management Option Pool | W22: =IF(W21>0,-($V21/(1+$V21))*SUM(W20:W21),0) | X22: =IF(X21>0,-($V21/(1+$V21))*SUM(X20:X21),0) | Y22: =IF(Y21>0,-($V21/(1+$V21))*SUM(Y20:Y21),0) | Z22: =IF(Z21>0,-($V21/(1+$V21))*SUM(Z20:Z21),0) | AA22: =IF(AA21>0,-($V21/(1+$V21))*SUM(AA20:AA21),0)
B23: Growth % | D23: =(D22/C22)-1 | E23: =(E22/D22)-1 | F23: =(F22/E22)-1 | G23: =(G22/F22)-1 | H23: =(H22/G22)-1 | I23: =(I22/H22)-1 | J23: =(J22/I22)-1 | K23: =(K22/J22)-1 | ... O23: =(O22/N22)-1 | S23: Sponsor Equity Value | W23: =SUM(W20:W22) | X23: =SUM(X20:X22) | Y23: =SUM(Y20:Y22) | Z23: =SUM(Z20:Z22) | AA23: =SUM(AA20:AA22)
B24: (-) Subcontractor Costs | C24: =C26-C22 | D24: =D26-D22 | E24: =E26-E22 | F24: =F26-F22 | G24: =G26-G22 | H24: =H26-H22 | I24: =-I25*I22 | J24: =-J25*J22 | K24: =-K25*K22 | L24: =-L25*L22 | M24: =-M25*M22 | N24: =-N25*N22 | O24: =-O25*O22 | P24: =(H24/C24)^(1/5)-1 | Q24: =(N24/I24)^(1/5)-1
B25: Contract Revenue % | C25: =-(C24/C22) | D25: =-(D24/D22) | E25: =-(E24/E22) | F25: =-(F24/F22) | G25: =-(G24/G22) | H25: =-(H24/H22) | I25: 0.47 | J25: =I25+($N25-$I25)/5 | K25: =J25+($N25-$I25)/5 | L25: =K25+($N25-$I25)/5 | M25: =L25+($N25-$I25)/5 | N25: 0.47 | O25: =N25 | S25: MOIC | W25: =W23/$E7 | X25: =X23/$E7 | Y25: =Y23/$E7 | Z25: =Z23/$E7 | AA25: =AA23/$E7
B26: Total Net Revenue | C26: ='Financial Overview'!D12 | D26: ='Financial Overview'!E12 | E26: ='Financial Overview'!F12 | F26: ='Financial Overview'!G12 | G26: ='Financial Overview'!H12 | H26: ='Financial Overview'!I12 | I26: ='Financial Overview'!J12 | J26: =J22+J24 | K26: =K22+K24 | L26: =L22+L24 | M26: =M22+M24 | N26: =N22+N24 | O26: =O22+O24 | P26: =(H26/C26)^(1/5)-1 | Q26: =(N26/I26)^(1/5)-1 | S26: IRR | W26: =XIRR(W27:W32,$S27:$S32) | X26: =XIRR(X27:X32,$S27:$S32) | Y26: =XIRR(Y27:Y32,$S27:$S32) | Z26: =XIRR(Z27:Z32,$S27:$S32) | AA26: =XIRR(AA27:AA32,$S27:$S32)
B27: Growth % | D27: =(D26/C26)-1 | E27: =(E26/D26)-1 | F27: =(F26/E26)-1 | G27: =(G26/F26)-1 | H27: =(H26/G26)-1 | I27: =(I26/H26)-1 | J27: =(J26/I26)-1 | K27: =(K26/J26)-1 | ... O27: =(O26/N26)-1 | S27: 46022 | W27: =-$E7 | X27: =-$E7 | Y27: =-$E7 | Z27: =-$E7 | AA27: =-$E7
B28: Contract Revenue % | C28: =C26/C22 | D28: =D26/D22 | E28: =E26/E22 | F28: =F26/F22 | G28: =G26/G22 | H28: =H26/H22 | I28: =I26/I22 | J28: =J26/J22 | ... O28: =O26/O22 | S28: 46387 | W28: =W23
B29: (-) COGS -- Direct Salaries & Wages | C29: =C31-C26 | D29: =D31-D26 | E29: =E31-E26 | F29: =F31-F26 | G29: =G31-G26 | H29: =H31-H26 | I29: =-I30*I$22 | J29: =-J30*J22 | K29: =-K30*K22 | L29: =-L30*L22 | M29: =-M30*M22 | N29: =-N30*N22 | O29: =-O30*O22 | P29: =(H29/C29)^(1/5)-1 | Q29: =(N29/I29)^(1/5)-1 | S29: 46752 | X29: =X23
B30: Contract Revenue % | C30: =-C29/C22 | D30: =-D29/D22 | E30: =-E29/E22 | F30: =-F29/F22 | G30: =-G29/G22 | H30: =-H29/H22 | I30: 0.16 | J30: =I30+($N30-$I30)/5 | K30: =J30+($N30-$I30)/5 | L30: =K30+($N30-$I30)/5 | M30: =L30+($N30-$I30)/5 | N30: 0.1425 | O30: =N30 | S30: 47118 | Y30: =Y23
B31: Gross Profit | C31: ='Financial Overview'!D16 | D31: ='Financial Overview'!E16 | E31: ='Financial Overview'!F16 | F31: ='Financial Overview'!G16 | G31: ='Financial Overview'!H16 | H31: ='Financial Overview'!I16 | I31: =I26+I29 | J31: =J26+J29 | K31: =K26+K29 | L31: =L26+L29 | M31: =M26+M29 | N31: =N26+N29 | O31: =O26+O29 | P31: =(H31/C31)^(1/5)-1 | Q31: =(N31/I31)^(1/5)-1 | S31: 47483 | Z31: =Z23
B32: Margin % (Net Revenue) | C32: =C31/C$26 | D32: =D31/D$26 | E32: =E31/E$26 | F32: =F31/F$26 | G32: =G31/G$26 | H32: =H31/H$26 | I32: =I31/I$26 | J32: =J31/J$26 | ... O32: =O31/O$26 | S32: 47848 | AA32: =AA23
B33: (-) OpEx | C33: =C35-C31 | D33: =D35-D31 | E33: =E35-E31 | F33: =F35-F31 | G33: =G35-G31 | H33: =H35-H31 | I33: =-I34*I$26 | J33: =-J34*J$26 | K33: =-K34*K$26 | L33: =-L34*L$26 | M33: =-M34*M$26 | N33: =-N34*N$26 | O33: =-O34*O$26 | P33: =(H33/C33)^(1/5)-1 | Q33: =(N33/I33)^(1/5)-1
B34: Net Revenue % | C34: =-C33/C$26 | D34: =-D33/D$26 | E34: =-E33/E$26 | F34: =-F33/F$26 | G34: =-G33/G$26 | H34: =-H33/H$26 | I34: 0.48425 | J34: =I34+($N34-$I34)/5 | K34: =J34+($N34-$I34)/5 | L34: =K34+($N34-$I34)/5 | M34: =L34+($N34-$I34)/5 | N34: 0.46 | O34: =N34
B35: Adjusted EBITDA | C35: ='Financial Overview'!D19 | D35: ='Financial Overview'!E19 | E35: ='Financial Overview'!F19 | F35: ='Financial Overview'!G19 | G35: ='Financial Overview'!H19 | H35: ='Financial Overview'!I19 | I35: =I31+I33 | J35: =J31+J33 | K35: =K31+K33 | L35: =L31+L33 | M35: =M31+M33 | N35: =N31+N33 | O35: =O31+O33 | P35: =(H35/C35)^(1/5)-1 | Q35: =(N35/I35)^(1/5)-1
B36: Margin % (Net Revenue) | C36: =C35/C$26 | D36: =D35/D$26 | E36: =E35/E$26 | F36: =F35/F$26 | G36: =G35/G$26 | H36: =H35/H$26 | I36: =I35/I$26 | J36: =J35/J$26 | ... O36: =O35/O$26
B37: Growth % | D37: =(D35/C35)-1 | E37: =(E35/D35)-1 | F37: =(F35/E35)-1 | G37: =(G35/F35)-1 | H37: =(H35/G35)-1 | I37: =(I35/H35)-1 | J37: =(J35/I35)-1 | K37: =(K35/J35)-1 | ... O37: =(O35/N35)-1
B38: (-) D&A | C38: -15.472 | D38: -18.743 | E38: -17.146 | F38: -17.489 | G38: -16.431 | H38: -14.745 | I38: =-I39*I$26 | J38: =-J39*J$26 | K38: =-K39*K$26 | L38: =-L39*L$26 | M38: =-M39*M$26 | N38: =-N39*N$26
B39: Net Revenue % | C39: =-C38/C$26 | D39: =-D38/D$26 | E39: =-E38/E$26 | F39: =-F38/F$26 | G39: =-G38/G$26 | H39: =-H38/H$26 | I39: 0.045 | J39: =I39+($N39-$I39)/5 | K39: =J39+($N39-$I39)/5 | L39: =K39+($N39-$I39)/5 | M39: =L39+($N39-$I39)/5 | N39: 0.035
B40: (-) Financing Fee Amortization | J40: =J78 | K40: =K78 | L40: =L78 | M40: =M78 | N40: =N78
B41: EBIT | C41: =C35+C38 | D41: =D35+D38 | E41: =E35+E38 | F41: =F35+F38 | G41: =G35+G38 | H41: =H35+H38 | I41: =I35+I38 | J41: =J35+J38+J40 | K41: =K35+K38+K40 | L41: =L35+L38+L40 | M41: =M35+M38+M40 | N41: =N35+N38+N40
...

Sheet PPT Support -->

Sheet Financial Overview
B2: Period | F2: Historical (FY Ending Dec.) | J2: Mgmt | K2: CAGR
B3: ($m) | C3: 2018 | D3: =C3+1 | E3: =D3+1 | F3: =E3+1 | G3: =F3+1 | H3: =G3+1 | I3: =H3+1 | J3: =I3+1 | K3: '19A-'24A
B4: Energy | C4: 196.832 | D4: 370.716 | E4: 324.178 | F4: 286.384 | G4: 357.46 | H4: 426.976 | I4: 473.309 | K4: =(I4/D4)^(1/5)-1
B5: % Growth | D5: =(D4/C4)-1 | E5: =(E4/D4)-1 | F5: =(F4/E4)-1 | G5: =(G4/F4)-1 | H5: =(H4/G4)-1 | I5: =(I4/H4)-1
B6: Engineering and Consulting | C6: 75.42 | D6: 72.383 | E6: 66.802 | F6: 67.371 | G6: 71.678 | H6: 83.119 | I6: 92.489 | K6: =(I6/D6)^(1/5)-1
B7: % Growth | D7: =(D6/C6)-1 | E7: =(E6/D6)-1 | F7: =(F6/E6)-1 | G7: =(G6/F6)-1 | H7: =(H6/G6)-1 | I7: =(I6/H6)-1
B8: Total Contract Revenue | C8: =SUM(C4,C6) | D8: =SUM(D4,D6) | E8: =SUM(E4,E6) | F8: =SUM(F4,F6) | G8: =SUM(G4,G6) | H8: =SUM(H4,H6) | I8: =SUM(I4,I6) | K8: =(I8/D8)^(1/5)-1
B9: % Growth | D9: =(D8/C8)-1 | E9: =(E8/D8)-1 | F9: =(F8/E8)-1 | G9: =(G8/F8)-1 | H9: =(H8/G8)-1 | I9: =(I8/H8)-1
B10: % Energy | D10: =D4/D$8 | E10: =E4/E$8 | F10: =F4/F$8 | G10: =G4/G$8 | H10: =H4/H$8 | I10: =I4/I$8
B11: % Engineering and Consulting | D11: =D6/D$8 | E11: =E6/E$8 | F11: =F6/F$8 | G11: =G6/G$8 | H11: =H6/H$8 | I11: =I6/I$8
B12: Total Net Revenue | C12: 139.559 | D12: 199.458 | E12: 194.542 | F12: 201.522 | G12: 226.551 | H12: 269.682 | I12: 296.325 | J12: 362.5 | K12: =(I12/D12)^(1/5)-1
B13: % Growth | D13: =(D12/C12)-1 | E13: =(E12/D12)-1 | F13: =(F12/E12)-1 | G13: =(G12/F12)-1 | H13: =(H12/G12)-1 | I13: =(I12/H12)-1 | J13: =(J12/I12)-1
B14: % Energy | D14: =142.902/D$12 | E14: =137.354/E$12 | F14: =140.115/F$12 | G14: =157.995/G$12 | H14: =190.373/H$12 | I14: =207.217/I$12
B15: % Engineering and Consulting | D15: =56.556/D$12 | E15: =57.188/E$12 | F15: =61.407/F$12 | G15: =68.556/G$12 | H15: =79.309/H$12 | I15: =89.108/I$12
B16: Gross Profit | C16: =C8-179.281 | D16: =D8-308.126 | E16: =E8-261.587 | F16: =F8-217.881 | G16: 143.579 | H16: 179.767 | I16: 202.782 | K16: =(I16/D16)^(1/5)-1
B17: % Margin (Contract Rev.) | C17: =C16/C8 | D17: =D16/D8 | E17: =E16/E8 | F17: =F16/F8 | G17: =G16/G8 | H17: =H16/H8 | I17: =I16/I8
B18: % Margin (Net Rev.) | C18: =C16/C12 | D18: =D16/D12 | E18: =E16/E12 | F18: =F16/F12 | G18: =G16/G12 | H18: =H16/H12 | I18: =I16/I12
B19: Adj. EBITDA | C19: 25.422 | D19: 37.716 | E19: 28.126 | F19: 27.526 | G19: 23.276 | H19: 45.695 | I19: 56.751 | J19: 77.5 | K19: =(I19/D19)^(1/5)-1
B20: % Margin (Contract Rev.) | C20: =C19/C8 | D20: =D19/D8 | E20: =E19/E8 | F20: =F19/F8 | G20: =G19/G8 | H20: =H19/H8 | I20: =I19/I8
B21: % Margin (Net Rev.) | C21: =C19/C12 | D21: =D19/D12 | E21: =E19/E12 | F21: =F19/F12 | G21: =G19/G12 | H21: =H19/H12 | I21: =I19/I12 | J21: =J19/J12

Sheet Financial Performance
C2: Energy | D2: C&E | E2: Net | F2: Contract | G2: Revenue | H2: Gross | I2: Gross | J2: Adj. | K2: Adj. EBITDA | L2: Operating | O2: LTM | P2: LTM | Q2: Shares | R2: LTM FCF / | S2: Debt | T2: Cash & | U2: Net | V2: Net Debt /
C3: Net Rev. | D3: Net Rev. | E3: Revenue | F3: Revenue | G3: Growth | H3: Profit | I3: Margin | J3: EBITDA | K3: Margin | L3: Cash Flow | M3: CapEx | N3: FCF | O3: FCF | P3: Conversion | Q3: Outstanding | R3: Share | S3: Outstanding | T3: Equivalents | U3: Debt | V3: Adj. EBITDA
B4: 3 | E4: =F4-43.824 | F4: 98.297
B5: =B4+1 | E5: =F5-40.373 | F5: 92.218 | H5: =F5-57.489 | I5: =H5/E5 | J5: 9.417 | K5: =J5/E5 | L5: 11.514 | M5: 4.602 | N5: =L5-M5
B6: 1 | E6: =F6-41.668 | F6: 91.838 | H6: =F6-60.478 | I6: =H6/E6 | J6: 2.347 | K6: =J6/E6 | L6: -7.754 | M6: 2.103 | N6: =L6-M6 | S6: 117.21 | T6: 7.651 | U6: =S6-T6
B7: =B6+1 | E7: =F7-49.771 | F7: 102.645 | H7: =F7-71.055 | I7: =H7/E7 | J7: 1.169 | K7: =J7/E7 | L7: =-3.569-L6 | M7: =4.344-M6 | N7: =L7-M7 | S7: 113.61 | T7: 5.811 | U7: =S7-T7
B8: 3 | C8: 41.068 | D8: 17.874 | E8: =C8+D8 | F8: 121.399 | G8: =(E8/E4)-1 | H8: =F8-83.877 | I8: =H8/E8 | J8: 7.981 | K8: =J8/E8 | L8: =4.503-SUM(L6:L7) | M8: =6.969-SUM(M6:M7) | N8: =L8-M8 | O8: =SUM(N5:N8) | P8: =O8/SUM(J5:J8) | Q8: 13.294922 | R8: =O8/Q8 | S8: 109.833 | T8: 8.818 | U8: =S8-T8 | V8: =U8/SUM(J5:J8)
B9: =B8+1 | C9: 47.254 | D9: 17.311 | E9: =C9+D9 | F9: 113.256 | G9: =(E9/E5)-1 | H9: =F9-70.149 | I9: =H9/E9 | J9: 11.779 | K9: =J9/E9 | L9: =9.433-SUM(L6:L8) | M9: =9.602-SUM(M6:M8) | N9: =L9-M9 | O9: =SUM(N6:N9) | P9: =O9/SUM(J6:J9) | Q9: 13.3872 | R9: =O9/Q9 | S9: 107.958 | T9: 8.806 | U9: =S9-T9 | V9: =U9/SUM(J6:J9)
B10: 1 | C10: 43.207 | D10: 18.484 | E10: =C10+D10 | F10: 102.603 | G10: =(E10/E6)-1 | H10: =F10-61.322 | I10: =H10/E10 | J10: 9.877 | K10: =J10/E10 | L10: 17.292 | M10: 3.488 | N10: =L10-M10 | O10: =SUM(N7:N10) | P10: =O10/SUM(J7:J10) | Q10: 13.489111 | R10: =O10/Q10 | S10: 102.223 | T10: 17.853 | U10: =S10-T10 | V10: =U10/SUM(J7:J10)
B11: =B10+1 | C11: 41.913 | D11: 20.022 | E11: =C11+D11 | F11: 119.077 | G11: =(E11/E7)-1 | H11: =F11-78.444 | I11: =H11/E11 | J11: 8.222 | K11: =J11/E11 | L11: =18.909-L10 | M11: =5.762-M10 | N11: =L11-M11 | O11: =SUM(N8:N11) | P11: =O11/SUM(J8:J11) | Q11: 13.594982 | R11: =O11/Q11 | S11: 102.988 | T11: 13.649 | U11: =S11-T11 | V11: =U11/SUM(J8:J11)
B12: =B11+1 | C12: 44.653 | D12: 20.631 | E12: =C12+D12 | F12: 132.738 | G12: =(E12/E8)-1 | H12: =F12-89.31 | I12: =H12/E12 | J12: 10.137 | K12: =J12/E12 | L12: =24.112-SUM(L10:L11) | M12: =7.583-SUM(M10:M11) | N12: =L12-M12 | O12: =SUM(N9:N12) | P12: =O12/SUM(J9:J12) | Q12: 13.646768 | R12: =O12/Q12 | S12: 100.495 | T12: 12.887 | U12: =S12-T12 | V12: =U12/SUM(J9:J12)
B13: =B12+1 | C13: 60.6 | D13: 20.172 | E13: =C13+D13 | F13: 155.677 | G13: =(E13/E9)-1 | H13: 54.425 | I13: =H13/E13 | J13: 17.459 | K13: =J13/E13 | L13: =39.214-SUM(L10:L12) | M13: =9.925-SUM(M10:M12) | N13: =L13-M13 | O13: =SUM(N10:N13) | P13: =O13/SUM(J10:J13) | Q13: 13.770106 | R13: =O13/Q13 | S13: 98.452 | T13: 23.397 | U13: =S13-T13 | V13: =U13/SUM(J10:J13)
B14: 1 | C14: 48.092 | D14: 20.838 | E14: =C14+D14 | F14: 122.489 | G14: =(E14/E10)-1 | H14: 47.418 | I14: =H14/E14 | J14: 11.034 | K14: =J14/E14 | L14: 26.949 | M14: 1.971 | N14: =L14-M14 | O14: =SUM(N11:N14) | P14: =O14/SUM(J11:J14) | Q14: 13.817074 | R14: =O14/Q14 | S14: 96.424 | T14: 46.925 | U14: =S14-T14 | V14: =U14/SUM(J11:J14)
B15: =B14+1 | C15: 50.296 | D15: 22.155 | E15: =C15+D15 | F15: 140.996 | G15: =(E15/E11)-1 | H15: 48.804 | I15: =H15/E15 | J15: 12.844 | K15: =J15/E15 | L15: =27.838-L14 | M15: =4.125-M14 | N15: =L15-M15 | O15: =SUM(N12:N15) | P15: =O15/SUM(J12:J15) | Q15: 13.994421 | R15: =O15/Q15 | S15: 94.53 | T15: 44.267 | U15: =S15-T15 | V15: =U15/SUM(J12:J15)
B16: =B15+1 | C16: 52.231 | D16: 23.458 | E16: =C16+D16 | F16: 158.252 | G16: =(E16/E12)-1 | H16: 51.601 | I16: =H16/E16 | J16: 15.177 | K16: =J16/E16 | L16: =38.611-SUM(L14:L15) | M16: =6.074-SUM(M14:M15) | N16: =L16-M16 | O16: =SUM(N13:N16) | P16: =O16/SUM(J13:J16) | Q16: 14.124865 | R16: =O16/Q16 | S16: 92.637 | T16: 53.106 | U16: =S16-T16 | V16: =U16/SUM(J13:J16)
B17: =B16+1 | C17: 56.598 | D17: 22.657 | E17: =C17+D17 | F17: 144.061 | G17: =(E17/E13)-1 | H17: 54.959 | I17: =H17/E17 | J17: 17.696 | K17: =J17/E17 | L17: =72.073-SUM(L14:L16) | M17: =8.413-SUM(M14:M16) | N17: =L17-M17 | O17: =SUM(N14:N17) | P17: =O17/SUM(J14:J17) | Q17: 14.407642 | R17: =O17/Q17 | S17: 90.137 | T17: 74.158 | U17: =S17-T17 | V17: =U17/SUM(J14:J17)
B18: 1 | C18: 60.168 | D18: 25.17 | E18: =C18+D18 | F18: 152.386 | G18: =(E18/E14)-1 | H18: 57.661 | I18: =H18/E18 | J18: 14.442 | K18: =J18/E18 | L18: 3.311 | M18: 2.31 | N18: =L18-M18 | O18: =SUM(N15:N18) | P18: =O18/SUM(J15:J18) | Q18: 14.496824 | R18: =O18/Q18 | S18: 87.5 | T18: 38.364 | U18: =S18-T18 | V18: =U18/SUM(J15:J18)
B19: =B18+1 | C19: 69.955 | D19: 25.013 | E19: =C19+D19 | F19: 173.473 | G19: =(E19/E15)-1 | H19: 68.325 | I19: =H19/E19 | J19: 21.922 | K19: =J19/E19 | L19: =28.724-L18 | M19: =4.517-M18 | N19: =L19-M19 | O19: =SUM(N16:N19) | P19: =O19/SUM(J16:J19) | Q19: 14.665087 | R19: =O19/Q19 | S19: 60 | T19: 32.348 | U19: =S19-T19 | V19: =U19/SUM(J16:J19)
B20: =B19+1 | C20: 69.214 | D20: 25.753 | E20: =C20+D20 | F20: 182.006 | G20: =(E20/E16)-1 | H20: 67.089 | I20: =H20/E20 | J20: 23.14 | K20: =J20/E20 | L20: =40.904-SUM(L18:L19) | M20: =6.924-SUM(M18:M19) | N20: =L20-M20 | O20: =SUM(N17:N20) | P20: =O20/SUM(J17:J20) | Q20: 14.749882 | R20: =O20/Q20 | S20: 49.375 | T20: 33.109 | U20: =S20-T20 | V20: =U20/SUM(J17:J20)
B21: CAGR | C21: =(C20/C8)^(1/3)-1 | D21: =(D20/D8)^(1/3)-1 | E21: =(E20/E8)^(1/3)-1 | F21: =(F20/F8)^(1/3)-1 | H21: =(H20/H8)^(1/3)-1 | I21: =I20-I8 | J21: =(J20/J8)^(1/3)-1 | K21: =K20-K8 | O21: =(O20/O8)^(1/3)-1 | P21: =SUM(N8:N20)/SUM(J8:J20) | R21: =R20/R8

Sheet Transaction Overview
B3: Sources | G3: Uses | Q3: Txn. | R3: Purchase
B4: Total Sponsor Equity | E4: =Model!E7 | G4: Purchase TEV | L4: =Model!L4 | N4: TEV / Contract Rev. | P4: Metric | Q4: TEV Mult. | R4: TEV Mult.
B5: New Debt | E5: =SUM(Model!E4:E6) | G5: Cash to Balance Sheet | L5: =Model!L5 | N5: LTM | P5: =SUM('Financial Performance'!F17:F20) | Q5: =L$7/P5 | R5: =L$4/P5
G6: Est. Fees & Expenses | L6: =SUM(Model!L6:L7) | N6: 2025E | P6: =Model!I22 | Q6: =L$7/P6 | R6: =L$4/P6
B7: Total Sources | E7: =SUM(E4:E5) | G7: Total Uses | L7: =SUM(L4:L6) | N7: NTM | P7: =(Model!I22*0.25)+(Model!J22*0.75) | Q7: =L$7/P7 | R7: =L$4/P7
I9: Adj. EBITDA(x) | N9: TEV / Adj. EBITDA
G10: Amount | I10: 45930 | J10: NTM | L10: Rate | N10: LTM | P10: =Model!U11 | Q10: =L$7/P10 | R10: =L$4/P10
B11: Cash | G11: =Model!L5 | I11: =G11/Model!U$11 | J11: =G11/Model!U$13 | N11: 2025E | P11: =Model!U12 | Q11: =L$7/P11 | R11: =L$4/P11
B12: Revolver | G12: =Model!E4 | I12: =G12/Model!U$11 | J12: =G12/Model!U$13 | L12: =INDEX(Model!I93:I98,MATCH("Interest",Model!B93:B98,0)) | N12: NTM | P12: =Model!U13 | Q12: =L$7/P12 | R12: =L$4/P12
B13: Term Loan | G13: =Model!E5 | I13: =G13/Model!U$11 | J13: =G13/Model!U$13 | L13: =Model!I104
B14: Senior Notes | G14: =Model!E6 | I14: =G14/Model!U$11 | J14: =G14/Model!U$13 | L14: =INDEX(Model!I107:I112,MATCH("Interest",Model!B107:B112,0)) | N14: TEV / Adj. EBITDA - CapEx
B15: Total Debt | G15: =SUM(G12:G14) | I15: =G15/Model!U$11 | J15: =G15/Model!U$13 | L15: 0.0733 | N15: LTM | P15: =P10-SUM('Financial Performance'!M17:M20) | Q15: =L$7/P15 | R15: =L$4/P15
B16: Total Sponsor Equity | G16: =Model!E7 | I16: =G16/Model!U$11 | J16: =G16/Model!U$13 | N16: 2025E | P16: =P11-Model!I71 | Q16: =L$7/P16 | R16: =L$4/P16
B17: Total Capitalization | G17: =SUM(G15:G16) | I17: =G17/Model!U$11 | J17: =G17/Model!U$13 | N17: NTM | P17: =P12-((Model!I71*0.25)+(Model!J71*0.75)) | Q17: =L$7/P17 | R17: =L$4/P17

Sheet Forward Curves -->

Sheet SOFR
B7: Secured Overnight Financing Rate (SOFR) Forward Curves
O9: Date | P9: 1-month Term SOFR | Q9: 3-month Term SOFR
O10: 46024 | P10: 0.0368891 | Q10: 0.0365609
O11: 46055 | P11: 0.0364384 | Q11: 0.0359812
O12: 46083 | P12: 0.036022 | Q12: 0.0354011
O13: 46114 | P13: 0.0352333 | Q13: 0.0345962
O14: 46146 | P14: 0.0345803 | Q14: 0.0337283
O15: 46175 | P15: 0.0336223 | Q15: 0.0331609
O16: 46205 | P16: 0.0328008 | Q16: 0.0326196
O17: 46237 | P17: 0.0327993 | Q17: 0.0320778
O18: 46267 | P18: 0.0319716 | Q18: 0.0315711
O19: 46297 | P19: 0.0312501 | Q19: 0.0312224
O20: 46328 | P20: 0.0312487 | Q20: 0.0310407
O21: 46358 | P21: 0.0309319 | Q21: 0.0308573
... O31: 46664 | P31: 0.0313501 | Q31: 0.0316139
B32: Latest curve as of 30 Dec 2025 | 16:00 EST | O32: 46693 | P32: 0.0315099 | Q32: 0.0317957
O33: 46723 | P33: 0.0317069 | Q33: 0.0319891
B34: For the latest rates, please visit: | O34: 46755 | P34: 0.0319183 | Q34: 0.0322029
B35: https://chathamdirect.com/rates | O35: 46785 | P35: 0.0321096 | Q35: 0.0323938
O36: 46814 | P36: 0.0323117 | Q36: 0.0325859
O37: 46846 | P37: 0.0325032 | Q37: 0.0327764
O38: 46875 | P38: 0.0326835 | Q38: 0.0329513
O39: 46906 | P39: 0.0328648 | Q39: 0.0331398
O40: 46937 | P40: 0.0330395 | Q40: 0.0332961
O41: 46967 | P41: 0.0332146 | Q41: 0.0334532
O42: 47001 | P42: 0.0333748 | Q42: 0.0336198
O43: 47028 | P43: 0.0335135 | Q43: 0.0337533
O44: 47059 | P44: 0.0336657 | Q44: 0.0338963
O45: 47091 | P45: 0.0338078 | Q45: 0.0340355
O46: 47120 | P46: 0.0339352 | Q46: 0.0341596
O47: 47151 | P47: 0.0340594 | Q47: 0.0342926
... O130: 49676 | P130: 0.0444625 | Q130: 0.0447214

Sheet 1-month Term SOFR
B7: 1-month Term SOFR Forward Curve
O9: Date | P9: 1-month Term SOFR
O10: 46024 | P10: 0.0368891
O11: 46055 | P11: 0.0364384
O12: 46083 | P12: 0.036022
O13: 46114 | P13: 0.0352333
O14: 46146 | P14: 0.0345803
O15: 46175 | P15: 0.0336223
O16: 46205 | P16: 0.0328008
O17: 46237 | P17: 0.0327993
O18: 46267 | P18: 0.0319716
O19: 46297 | P19: 0.0312501
O20: 46328 | P20: 0.0312487
O21: 46358 | P21: 0.0309319
... O31: 46664 | P31: 0.0313501
B32: Latest curve as of 30 Dec 2025 | 16:00 EST | O32: 46693 | P32: 0.0315099
O33: 46723 | P33: 0.0317069
B34: For the latest rates, please visit: | O34: 46755 | P34: 0.0319183
B35: https://chathamdirect.com/rates | O35: 46785 | P35: 0.0321096
O36: 46814 | P36: 0.0323117
O37: 46846 | P37: 0.0325032
O38: 46875 | P38: 0.0326835
O39: 46906 | P39: 0.0328648
O40: 46937 | P40: 0.0330395
O41: 46967 | P41: 0.0332146
O42: 47001 | P42: 0.0333748
O43: 47028 | P43: 0.0335135
O44: 47059 | P44: 0.0336657
O45: 47091 | P45: 0.0338078
O46: 47120 | P46: 0.0339352
O47: 47151 | P47: 0.0340594
... O130: 49676 | P130: 0.0444625

Sheet 3-month Term SOFR
B7: 3-month Term SOFR Forward Curve
O9: Date | P9: 3-month Term SOFR
O10: 46024 | P10: 0.0365609
O11: 46055 | P11: 0.0359812
O12: 46083 | P12: 0.0354011
O13: 46114 | P13: 0.0345962
O14: 46146 | P14: 0.0337283
O15: 46175 | P15: 0.0331609
O16: 46205 | P16: 0.0326196
O17: 46237 | P17: 0.0320778
O18: 46267 | P18: 0.0315711
O19: 46297 | P19: 0.0312224
O20: 46328 | P20: 0.0310407
O21: 46358 | P21: 0.0308573
... O31: 46664 | P31: 0.0316139
B32: Latest curve as of 30 Dec 2025 | 16:00 EST | O32: 46693 | P32: 0.0317957
O33: 46723 | P33: 0.0319891
B34: For the latest rates, please visit: | O34: 46755 | P34: 0.0322029
B35: https://chathamdirect.com/rates | O35: 46785 | P35: 0.0323938
O36: 46814 | P36: 0.0325859
O37: 46846 | P37: 0.0327764
O38: 46875 | P38: 0.0329513
O39: 46906 | P39: 0.0331398
O40: 46937 | P40: 0.0332961
O41: 46967 | P41: 0.0334532
O42: 47001 | P42: 0.0336198
O43: 47028 | P43: 0.0337533
O44: 47059 | P44: 0.0338963
O45: 47091 | P45: 0.0340355
O46: 47120 | P46: 0.0341596
O47: 47151 | P47: 0.0342926
... O130: 49676 | P130: 0.0447214

Sheet Fed Projections
B7: Fed Projections
B9: Rates | C9: 2025 | D9: 2026 | E9: 2027 | F9: 2028 | G9: 2029
B10: Median | C10: 0.03625 | D10: 0.03375 | E10: 0.03125 | F10: 0.03125 | G10: 0.03
B11: 0.02125 | D11: 1
B12: 0.02375 | E12: 1
B13: 0.02625 | D13: 1 | E13: 2 | F13: 3 | G13: 3
B14: 0.0275 | F14: 1 | G14: 1
B15: 0.02875 | D15: 2 | E15: 3 | F15: 3 | G15: 1
B16: 0.03 | G16: 5
B17: 0.03125 | D17: 4 | E17: 6 | F17: 6 | G17: 2
B18: 0.0325 | G18: 1
B19: 0.03375 | C19: 1 | D19: 4 | E19: 3 | F19: 2 | G19: 2
B20: 0.035 | G20: 1
B21: 0.03625 | C21: 12 | D21: 4 | E21: 2 | F21: 2 | G21: 1
B22: 0.0375 | G22: 1
B23: 0.03875 | C23: 6 | D23: 3 | E23: 2 | F23: 2 | G23: 1
B24: 10 Dec 2025
B26: For the latest rates, please visit:
B27: https://chathamdirect.com/rates
